Workbook

Sheet data
A1: Publisher ID | B1: Publisher Name | C1: Keyword ID | D1: Keyword | E1: Match Type | F1: Campaign | G1: Keyword Group | H1: Category | I1: Bid Strategy | J1: Keyword Type | K1: Status | L1: Search Engine Bid | M1: Clicks | N1: Click Charges | O1: Avg. Cost per Click | P1: Impressions | Q1: Engine Click Thru % | R1: Avg. Pos. | S1: Trans. Conv. % | T1: Total Cost/ Trans. | U1: Amount | V1: Total Cost | W1: Net Revenue | X1: Return on Ad Dollar Spent | Y1: Total Volume of Bookings | Z1: Avg. Revenue per Booking | AA1: Probability of Booking
A2: K2615 | B2: Yahoo - US | C2: 43000000039657988 | D2: fly to florence | E2: Advanced | F2: Western Europe Destinations | G2: Florence | H2: uncategorized | J2: Unassigned | K2: Live | L2: 6.25 | M2: 1 | N2: 2.3125 | O2: 2.3125 | P2: 11 | Q2: 9.0909091 | R2: 1.2727273 | S2: 900 | T2: =N2/Y2 -> 0.25694444 | U2: 8777.95 | V2: =N2 -> 2.3125 | W2: =U2-V2 -> 8775.6375 | X2: =IF(V2=0,0,(U2-V2)/V2) -> 3794.8703 | Y2: 9 | Z2: =IF(Y2=0,"NA",U2/Y2) -> 975.32778 | AA2: =(Q2/100*S2/100) -> 0.81818182
A3: K2615 | B3: Yahoo - US | C3: 43000000039651113 | D3: low international airfare | E3: Advanced | F3: Geo Targeted DC | G3: Low International DC | H3: uncategorized | J3: Unassigned | K3: Paused | L3: 6.25 | M3: 1 | N3: 0.625 | O3: 0.625 | P3: 6 | Q3: 16.666667 | R3: 1 | S3: 100 | T3: =N3/Y3 -> 0.625 | U3: 1574.2 | V3: =N3 -> 0.625 | W3: =U3-V3 -> 1573.575 | X3: =IF(V3=0,0,(U3-V3)/V3) -> 2517.72 | Y3: 1 | Z3: =IF(Y3=0,"NA",U3/Y3) -> 1574.2 | AA3: =(Q3/100*S3/100) -> 0.16666667
A4: K2003 | B4: MSN - Global | C4: 43000000019452431 | D4: air discount france ticket | E4: Broad | F4: Air France Brand & French Destinations | G4: France | H4: uncategorized | I4: Position 2-5 Bid Strategy | J4: Unassigned | K4: Deactivated | L4: 0 | M4: 1 | N4: 0.3875 | O4: 0.3875 | P4: 9 | Q4: 11.111111 | R4: 1.1111111 | S4: 100 | T4: =N4/Y4 -> 0.3875 | U4: 390.15 | V4: =N4 -> 0.3875 | W4: =U4-V4 -> 389.7625 | X4: =IF(V4=0,0,(U4-V4)/V4) -> 1005.8387 | Y4: 1 | Z4: =IF(Y4=0,"NA",U4/Y4) -> 390.15 | AA4: =(Q4/100*S4/100) -> 0.11111111
A5: K1175 | B5: Google - Global | C5: 43000000005663331 | D5: [airfrance] | E5: Exact | F5: Air France Global Campaign | G5: Air France | H5: airfrance | I5: Position 1- 3 | J5: Unassigned | K5: Unavailable | L5: 7.5 | M5: 59 | N5: 2.3124998 | O5: 0.039194912 | P5: 401 | Q5: 14.713217 | R5: 2 | S5: 3.3898305 | T5: =N5/Y5 -> 1.1562499 | U5: 1665.15 | V5: =N5 -> 2.3124998 | W5: =U5-V5 -> 1662.8375 | X5: =IF(V5=0,0,(U5-V5)/V5) -> 719.06492 | Y5: 2 | Z5: =IF(Y5=0,"NA",U5/Y5) -> 832.575 | AA5: =(Q5/100*S5/100) -> 0.0049875312
A6: K1123 | B6: Overture - Global | C6: 43000000005421354 | D6: air france online booking | E6: Standard | F6: Unassigned | G6: Unassigned | H6: airfrance | I6: Position 1-2 Target | J6: Unassigned | K6: Paused | L6: 0.25 | M6: 8 | N6: 2.2 | O6: 0.275 | P6: 318 | Q6: 2.5157233 | R6: 2.9757862 | S6: 12.5 | T6: =N6/Y6 -> 2.2 | U6: 935 | V6: =N6 -> 2.2 | W6: =U6-V6 -> 932.8 | X6: =IF(V6=0,0,(U6-V6)/V6) -> 424 | Y6: 1 | Z6: =IF(Y6=0,"NA",U6/Y6) -> 935 | AA6: =(Q6/100*S6/100) -> 0.0031446541
A7: K1123 | B7: Overture - Global | C7: 43000000005421146 | D7: airfrance,com | E7: Standard | F7: Unassigned | G7: Unassigned | H7: airfrancewebsite | I7: Position 1-2 Target | J7: Unassigned | K7: Paused | L7: 0.125 | M7: 42 | N7: 5.25 | O7: 0.125 | P7: 722 | Q7: 5.8171745 | R7: 1.1290859 | S7: 4.7619048 | T7: =N7/Y7 -> 2.625 | U7: 1817.3 | V7: =N7 -> 5.25 | W7: =U7-V7 -> 1812.05 | X7: =IF(V7=0,0,(U7-V7)/V7) -> 345.15238 | Y7: 2 | Z7: =IF(Y7=0,"NA",U7/Y7) -> 908.65 | AA7: =(Q7/100*S7/100) -> 0.0027700831
A8: K435 | B8: Google - US | C8: 43000000014110441 | D8: paris cheap airline | E8: Broad | F8: Geo Targeted San Francisco | G8: San Francisco to Paris Sale | H8: uncategorized | I8: Position 5-10 Bid Strategy | J8: Unassigned | K8: Paused | L8: 6.25 | M8: 3 | N8: 5.2125 | O8: 1.7375 | P8: 13 | Q8: 23.076923 | R8: 1 | S8: 33.333333 | T8: =N8/Y8 -> 5.2125 | U8: 1685.55 | V8: =N8 -> 5.2125 | W8: =U8-V8 -> 1680.3375 | X8: =IF(V8=0,0,(U8-V8)/V8) -> 322.36691 | Y8: 1 | Z8: =IF(Y8=0,"NA",U8/Y8) -> 1685.55 | AA8: =(Q8/100*S8/100) -> 0.076923077
A9: K1122 | B9: Overture - US | C9: 43000000014278681 | D9: airfrance.us | E9: Standard | F9: Unassigned | G9: Unassigned | H9: airfrance | I9: Position 1-4 Bid Strategy | J9: Unassigned | K9: Paused | L9: 0.325 | M9: 47 | N9: 11.8 | O9: 0.25106383 | P9: 547 | Q9: 8.5923218 | R9: 1.1819013 | S9: 4.2553191 | T9: =N9/Y9 -> 5.8999999 | U9: 3796.1 | V9: =N9 -> 11.8 | W9: =U9-V9 -> 3784.3 | X9: =IF(V9=0,0,(U9-V9)/V9) -> 320.7034 | Y9: 2 | Z9: =IF(Y9=0,"NA",U9/Y9) -> 1898.05 | AA9: =(Q9/100*S9/100) -> 0.0036563071
A10: K1123 | B10: Overture - Global | C10: 43000000005421374 | D10: air travel to paris | E10: Standard | F10: Unassigned | G10: Unassigned | H10: paris | I10: Position 1-2 Target | J10: Unassigned | K10: Unavailable | L10: 7.5 | M10: 13 | N10: 5.2125 | O10: 0.40096154 | P10: 448 | Q10: 2.9017857 | R10: 1.8564732 | S10: 7.6923077 | T10: =N10/Y10 -> 5.2125 | U10: 1513 | V10: =N10 -> 5.2125 | W10: =U10-V10 -> 1507.7875 | X10: =IF(V10=0,0,(U10-V10)/V10) -> 289.26379 | Y10: 1 | Z10: =IF(Y10=0,"NA",U10/Y10) -> 1513 | AA10: =(Q10/100*S10/100) -> 0.0022321429
A11: K1175 | B11: Google - Global | C11: 43000000019449172 | D11: air france site | E11: Broad | F11: Air France Brand & French Destinations | G11: Air France Website | H11: uncategorized | J11: Unassigned | K11: Unavailable | L11: 5 | M11: 19 | N11: 8.2374999 | O11: 0.43355262 | P11: 129 | Q11: 14.728682 | R11: 1.0302326 | S11: 5.2631579 | T11: =N11/Y11 -> 8.2374999 | U11: 2348.55 | V11: =N11 -> 8.2374999 | W11: =U11-V11 -> 2340.3125 | X11: =IF(V11=0,0,(U11-V11)/V11) -> 284.10471 | Y11: 1 | Z11: =IF(Y11=0,"NA",U11/Y11) -> 2348.55 | AA11: =(Q11/100*S11/100) -> 0.007751938
A12: K1123 | B12: Overture - Global | C12: 43000000005421298 | D12: cheap fare to paris | E12: Advanced | F12: Unassigned | G12: Unassigned | H12: paris | I12: Position 1-2 Target | J12: Unassigned | K12: Sent | L12: 0.6875 | M12: 29 | N12: 26.6125 | O12: 0.91767241 | P12: 559 | Q12: 5.1878354 | R12: 2.3334526 | S12: 6.8965517 | T12: =N12/Y12 -> 13.30625 | U12: 7418.8 | V12: =N12 -> 26.6125 | W12: =U12-V12 -> 7392.1875 | X12: =IF(V12=0,0,(U12-V12)/V12) -> 277.77125 | Y12: 2 | Z12: =IF(Y12=0,"NA",U12/Y12) -> 3709.4 | AA12: =(Q12/100*S12/100) -> 0.0035778175
A13: K1122 | B13: Overture - US | C13: 43000000014278799 | D13: air france.com | E13: Standard | F13: Unassigned | G13: Unassigned | H13: airfrance | I13: Position 1-4 Bid Strategy | J13: Unassigned | K13: Paused | L13: 0.3125 | M13: 273 | N13: 46.349998 | O13: 0.16978021 | P13: 3171 | Q13: 8.6092715 | R13: 1.0063072 | S13: 3.6630037 | T13: =N13/Y13 -> 4.6349998 | U13: 11271.85 | V13: =N13 -> 46.349998 | W13: =U13-V13 -> 11225.5 | X13: =IF(V13=0,0,(U13-V13)/V13) -> 242.18987 | Y13: 10 | Z13: =IF(Y13=0,"NA",U13/Y13) -> 1127.185 | AA13: =(Q13/100*S13/100) -> 0.0031535793
A14: K435 | B14: Google - US | C14: 43000000017532136 | D14: air france us | E14: Broad | F14: Air France Branded | G14: Air France Website | H14: uncategorized | J14: Unassigned | K14: Live | L14: 10 | M14: 231 | N14: 99.549999 | O14: 0.43095237 | P14: 1277 | Q14: 18.089272 | R14: 1.0226077 | S14: 8.6580087 | T14: =N14/Y14 -> 4.9774999 | U14: 23076.65 | V14: =N14 -> 99.549999 | W14: =U14-V14 -> 22977.1 | X14: =IF(V14=0,0,(U14-V14)/V14) -> 230.80965 | Y14: 20 | Z14: =IF(Y14=0,"NA",U14/Y14) -> 1153.8325 | AA14: =(Q14/100*S14/100) -> 0.015661707
A15: K435 | B15: Google - US | C15: 43000000017532129 | D15: airfrance | E15: Broad | F15: Air France Branded | G15: Air France Website | H15: uncategorized | J15: Unassigned | K15: Paused | L15: 10 | M15: 907 | N15: 235.11249 | O15: 0.25921995 | P15: 4352 | Q15: 20.840993 | R15: 1.0105836 | S15: 2.8665932 | T15: =N15/Y15 -> 9.0427883 | U15: 48551.15 | V15: =N15 -> 235.11249 | W15: =U15-V15 -> 48316.038 | X15: =IF(V15=0,0,(U15-V15)/V15) -> 205.50179 | Y15: 26 | Z15: =IF(Y15=0,"NA",U15/Y15) -> 1867.3519 | AA15: =(Q15/100*S15/100) -> 0.0059742647
A16: K1122 | B16: Overture - US | C16: 43000000014278804 | D16: cdg flight | E16: Standard | F16: Unassigned | G16: Unassigned | H16: paris | I16: Position 2-5 Bid Strategy | J16: Unassigned | K16: Paused | L16: 0.125 | M16: 18 | N16: 4.75 | O16: 0.26388889 | P16: 169 | Q16: 10.650888 | R16: 1.6621302 | S16: 5.5555556 | T16: =N16/Y16 -> 4.75 | U16: 896.75 | V16: =N16 -> 4.75 | W16: =U16-V16 -> 892 | X16: =IF(V16=0,0,(U16-V16)/V16) -> 187.78947 | Y16: 1 | Z16: =IF(Y16=0,"NA",U16/Y16) -> 896.75 | AA16: =(Q16/100*S16/100) -> 0.0059171598
A17: K435 | B17: Google - US | C17: 43000000017532133 | D17: airfrance us | E17: Broad | F17: Air France Branded | G17: Air France Website | H17: uncategorized | J17: Unassigned | K17: Live | L17: 10 | M17: 207 | N17: 30.787498 | O17: 0.14873187 | P17: 730 | Q17: 28.356164 | R17: 1 | S17: 2.4154589 | T17: =N17/Y17 -> 6.1574996 | U17: 5733.25 | V17: =N17 -> 30.787498 | W17: =U17-V17 -> 5702.4625 | X17: =IF(V17=0,0,(U17-V17)/V17) -> 185.22007 | Y17: 5 | Z17: =IF(Y17=0,"NA",U17/Y17) -> 1146.65 | AA17: =(Q17/100*S17/100) -> 0.0068493151
A18: K435 | B18: Google - US | C18: 43000000014113402 | D18: france airline ticket | E18: Broad | F18: Geo Targeted New York | G18: New York to France Sale | H18: uncategorized | I18: Position 5-10 Bid Strategy | J18: Unassigned | K18: Live | L18: 6.25 | M18: 2 | N18: 2.6875 | O18: 1.34375 | P18: 24 | Q18: 8.3333333 | R18: 1.5416667 | S18: 50 | T18: =N18/Y18 -> 2.6875 | U18: 494.7 | V18: =N18 -> 2.6875 | W18: =U18-V18 -> 492.0125 | X18: =IF(V18=0,0,(U18-V18)/V18) -> 183.07442 | Y18: 1 | Z18: =IF(Y18=0,"NA",U18/Y18) -> 494.7 | AA18: =(Q18/100*S18/100) -> 0.041666667
A19: K435 | B19: Google - US | C19: 43000000013069003 | D19: airfrance website | E19: Broad | F19: Air France Branded | G19: Air France Website | H19: uncategorized | I19: Position 2-5 Bid Strategy | J19: Unassigned | K19: Live | L19: 0.7125 | M19: 10 | N19: 9.9375 | O19: 0.99375 | P19: 80 | Q19: 12.5 | R19: 1.0625 | S19: 10 | T19: =N19/Y19 -> 9.9375 | U19: 1815.6 | V19: =N19 -> 9.9375 | W19: =U19-V19 -> 1805.6625 | X19: =IF(V19=0,0,(U19-V19)/V19) -> 181.70189 | Y19: 1 | Z19: =IF(Y19=0,"NA",U19/Y19) -> 1815.6 | AA19: =(Q19/100*S19/100) -> 0.0125
A20: K1123 | B20: Overture - Global | C20: 43000000005420920 | D20: airplane france ticket | E20: Advanced | F20: Unassigned | G20: Unassigned | H20: airline | I20: Position 1-2 Target | J20: Unassigned | K20: Paused | L20: 0.4375 | M20: 16 | N20: 8.3125 | O20: 0.51953125 | P20: 6073 | Q20: 0.26346122 | R20: 2.4634283 | S20: 6.25 | T20: =N20/Y20 -> 8.3125 | U20: 1473.9 | V20: =N20 -> 8.3125 | W20: =U20-V20 -> 1465.5875 | X20: =IF(V20=0,0,(U20-V20)/V20) -> 176.31128 | Y20: 1 | Z20: =IF(Y20=0,"NA",U20/Y20) -> 1473.9 | AA20: =(Q20/100*S20/100) -> 0.00016466326
A21: K435 | B21: Google - US | C21: 43000000014115425 | D21: france airfare sale | E21: Broad | F21: Geo Targeted Miami | G21: Miami to France Sale | H21: uncategorized | I21: Position 5-10 Bid Strategy | J21: Unassigned | K21: Paused | L21: 6.25 | M21: 1 | N21: 2.7625 | O21: 2.7625 | P21: 2 | Q21: 50 | R21: 1 | S21: 100 | T21: =N21/Y21 -> 2.7625 | U21: 470.05 | V21: =N21 -> 2.7625 | W21: =U21-V21 -> 467.2875 | X21: =IF(V21=0,0,(U21-V21)/V21) -> 169.15385 | Y21: 1 | Z21: =IF(Y21=0,"NA",U21/Y21) -> 470.05 | AA21: =(Q21/100*S21/100) -> 0.5
A22: K1123 | B22: Overture - Global | C22: 43000000005421434 | D22: air france schedule | E22: Advanced | F22: Unassigned | G22: Unassigned | H22: airfrance | I22: Position 1-2 Target | J22: Unassigned | K22: Paused | L22: 0.325 | M22: 30 | N22: 10.7125 | O22: 0.35708333 | P22: 2192 | Q22: 1.3686131 | R22: 1.5193431 | S22: 3.3333333 | T22: =N22/Y22 -> 10.7125 | U22: 1785 | V22: =N22 -> 10.7125 | W22: =U22-V22 -> 1774.2875 | X22: =IF(V22=0,0,(U22-V22)/V22) -> 165.62778 | Y22: 1 | Z22: =IF(Y22=0,"NA",U22/Y22) -> 1785 | AA22: =(Q22/100*S22/100) -> 0.00045620438
A23: K1123 | B23: Overture - Global | C23: 43000000009683629 | D23: airfare to tahiti | E23: Standard | F23: Unassigned | G23: Unassigned | H23: tahiti | J23: Unassigned | K23: Paused | L23: 10 | M23: 6 | N23: 12.275 | O23: 2.0458333 | P23: 102 | Q23: 5.8823529 | R23: 4.1637255 | S23: 16.666667 | T23: =N23/Y23 -> 12.275 | U23: 1989 | V23: =N23 -> 12.275 | W23: =U23-V23 -> 1976.725 | X23: =IF(V23=0,0,(U23-V23)/V23) -> 161.03666 | Y23: 1 | Z23: =IF(Y23=0,"NA",U23/Y23) -> 1989 | AA23: =(Q23/100*S23/100) -> 0.0098039216
A24: K435 | B24: Google - US | C24: 43000000014122527 | D24: france flights | E24: Broad | F24: Geo Targeted DC | G24: DC to France Sale | H24: uncategorized | I24: Position 5-10 Bid Strategy | J24: Unassigned | K24: Unavailable | L24: 6.25 | M24: 6 | N24: 18.35 | O24: 3.0583333 | P24: 137 | Q24: 4.379562 | R24: 1.2026277 | S24: 50 | T24: =N24/Y24 -> 6.1166666 | U24: 2810.1 | V24: =N24 -> 18.35 | W24: =U24-V24 -> 2791.75 | X24: =IF(V24=0,0,(U24-V24)/V24) -> 152.13896 | Y24: 3 | Z24: =IF(Y24=0,"NA",U24/Y24) -> 936.7 | AA24: =(Q24/100*S24/100) -> 0.02189781
A25: K435 | B25: Google - US | C25: 43000000014201100 | D25: international airfares | E25: Broad | F25: Geo Targeted Detroit | G25: International Detroit | H25: uncategorized | I25: Position 5-10 Bid Strategy | J25: Unassigned | K25: Unavailable | L25: 6.25 | M25: 2 | N25: 6.6 | O25: 3.3 | P25: 79 | Q25: 2.5316456 | R25: 3.0050633 | S25: 50 | T25: =N25/Y25 -> 6.6 | U25: 923.95 | V25: =N25 -> 6.6 | W25: =U25-V25 -> 917.35 | X25: =IF(V25=0,0,(U25-V25)/V25) -> 138.99242 | Y25: 1 | Z25: =IF(Y25=0,"NA",U25/Y25) -> 923.95 | AA25: =(Q25/100*S25/100) -> 0.012658228
A26: K435 | B26: Google - US | C26: 43000000014113704 | D26: france air ticket | E26: Broad | F26: Geo Targeted New York | G26: New York to France Sale | H26: uncategorized | I26: Position 5-10 Bid Strategy | J26: Unassigned | K26: Live | L26: 6.25 | M26: 12 | N26: 19.4 | O26: 1.6166667 | P26: 116 | Q26: 10.344828 | R26: 1.0940517 | S26: 33.333333 | T26: =N26/Y26 -> 4.85 | U26: 2706.4 | V26: =N26 -> 19.4 | W26: =U26-V26 -> 2687 | X26: =IF(V26=0,0,(U26-V26)/V26) -> 138.50515 | Y26: 4 | Z26: =IF(Y26=0,"NA",U26/Y26) -> 676.6 | AA26: =(Q26/100*S26/100) -> 0.034482759
A27: K1122 | B27: Overture - US | C27: 43000000017532937 | D27: airfrance.com/us | E27: Standard | F27: Unassigned | G27: Unassigned | H27: airfrance | J27: Unassigned | K27: Paused | L27: 7.5 | M27: 17 | N27: 5.5874999 | O27: 0.32867646 | P27: 98 | Q27: 17.346939 | R27: 0.95918367 | S27: 5.8823529 | T27: =N27/Y27 -> 5.5874999 | U27: 778.6 | V27: =N27 -> 5.5874999 | W27: =U27-V27 -> 773.0125 | X27: =IF(V27=0,0,(U27-V27)/V27) -> 138.34676 | Y27: 1 | Z27: =IF(Y27=0,"NA",U27/Y27) -> 778.6 | AA27: =(Q27/100*S27/100) -> 0.010204082
A28: K435 | B28: Google - US | C28: 43000000014127450 | D28: paris cheap ticket | E28: Broad | F28: Geo Targeted Boston | G28: Boston to Paris Sale | H28: uncategorized | I28: Position 5-10 Bid Strategy | J28: Unassigned | K28: Paused | L28: 6.25 | M28: 3 | N28: 5.1375 | O28: 1.7125 | P28: 18 | Q28: 16.666667 | R28: 1.8333333 | S28: 33.333333 | T28: =N28/Y28 -> 5.1375 | U28: 676.6 | V28: =N28 -> 5.1375 | W28: =U28-V28 -> 671.4625 | X28: =IF(V28=0,0,(U28-V28)/V28) -> 130.6983 | Y28: 1 | Z28: =IF(Y28=0,"NA",U28/Y28) -> 676.6 | AA28: =(Q28/100*S28/100) -> 0.055555556
A29: K435 | B29: Google - US | C29: 43000000014118997 | D29: paris cheap flights | E29: Broad | F29: Geo Targeted Houston | G29: Houston to Paris Sale | H29: uncategorized | I29: Position 5-10 Bid Strategy | J29: Unassigned | K29: Paused | L29: 6.25 | M29: 21 | N29: 43.3875 | O29: 2.0660714 | P29: 174 | Q29: 12.068966 | R29: 1.3214368 | S29: 14.285714 | T29: =N29/Y29 -> 14.4625 | U29: 5638.05 | V29: =N29 -> 43.3875 | W29: =U29-V29 -> 5594.6625 | X29: =IF(V29=0,0,(U29-V29)/V29) -> 128.94641 | Y29: 3 | Z29: =IF(Y29=0,"NA",U29/Y29) -> 1879.35 | AA29: =(Q29/100*S29/100) -> 0.017241379
A30: K1122 | B30: Overture - US | C30: 43000000007003938 | D30: tunis | E30: Standard | F30: Unassigned | G30: Unassigned | H30: regional | I30: Position 1-4 Bid Strategy | J30: Unassigned | K30: Paused | L30: 11.25 | M30: 36 | N30: 25.375 | O30: 0.7048611 | P30: 832 | Q30: 4.3269231 | R30: 1.4074519 | S30: 8.3333333 | T30: =N30/Y30 -> 8.4583332 | U30: 3254.65 | V30: =N30 -> 25.375 | W30: =U30-V30 -> 3229.275 | X30: =IF(V30=0,0,(U30-V30)/V30) -> 127.26207 | Y30: 3 | Z30: =IF(Y30=0,"NA",U30/Y30) -> 1084.8833 | AA30: =(Q30/100*S30/100) -> 0.0036057692
A31: K2615 | B31: Yahoo - US | C31: 43000000029356928 | D31: france travel agency | E31: Standard | F31: Paris & France Terms | G31: France | H31: uncategorized | J31: Unassigned | K31: Live | L31: 6.25 | M31: 5 | N31: 15.4375 | O31: 3.0875 | P31: 167 | Q31: 2.994012 | R31: 1.2392814 | S31: 40 | T31: =N31/Y31 -> 7.71875 | U31: 1978.8 | V31: =N31 -> 15.4375 | W31: =U31-V31 -> 1963.3625 | X31: =IF(V31=0,0,(U31-V31)/V31) -> 127.18138 | Y31: 2 | Z31: =IF(Y31=0,"NA",U31/Y31) -> 989.4 | AA31: =(Q31/100*S31/100) -> 0.011976048
A32: K1175 | B32: Google - Global | C32: 43000000005663431 | D32: air france airlines | E32: Broad | F32: Air France Global Campaign | G32: Air France | H32: airfrance | I32: Position 1- 3 | J32: Unassigned | K32: Unavailable | L32: 1.25 | M32: 228 | N32: 55.312498 | O32: 0.24259868 | P32: 3747 | Q32: 6.0848679 | R32: 1.4166533 | S32: 1.754386 | T32: =N32/Y32 -> 13.828124 | U32: 6873.1 | V32: =N32 -> 55.312498 | W32: =U32-V32 -> 6817.7875 | X32: =IF(V32=0,0,(U32-V32)/V32) -> 123.25944 | Y32: 4 | Z32: =IF(Y32=0,"NA",U32/Y32) -> 1718.275 | AA32: =(Q32/100*S32/100) -> 0.0010675207
A33: K1175 | B33: Google - Global | C33: 43000000005663208 | D33: lyon airfare | E33: Broad | F33: Air France Global Campaign | G33: Lyon | H33: lyon | I33: Position 1- 3 | J33: Unassigned | K33: Unavailable | L33: 1.25 | M33: 12 | N33: 15.025 | O33: 1.2520833 | P33: 1030 | Q33: 1.1650485 | R33: 1.3096117 | S33: 16.666667 | T33: =N33/Y33 -> 7.5124999 | U33: 1836 | V33: =N33 -> 15.025 | W33: =U33-V33 -> 1820.975 | X33: =IF(V33=0,0,(U33-V33)/V33) -> 121.19634 | Y33: 2 | Z33: =IF(Y33=0,"NA",U33/Y33) -> 918 | AA33: =(Q33/100*S33/100) -> 0.0019417476
A34: K1123 | B34: Overture - Global | C34: 43000000005421430 | D34: air france web site | E34: Standard | F34: Unassigned | G34: Unassigned | H34: airfrance | I34: Position 1-2 Target | J34: Unassigned | K34: Paused | L34: 0.2875 | M34: 17 | N34: 5.3875 | O34: 0.31691176 | P34: 752 | Q34: 2.2606383 | R34: 2.2155585 | S34: 5.8823529 | T34: =N34/Y34 -> 5.3875 | U34: 637.5 | V34: =N34 -> 5.3875 | W34: =U34-V34 -> 632.1125 | X34: =IF(V34=0,0,(U34-V34)/V34) -> 117.32947 | Y34: 1 | Z34: =IF(Y34=0,"NA",U34/Y34) -> 637.5 | AA34: =(Q34/100*S34/100) -> 0.0013297872
A35: K1175 | B35: Google - Global | C35: 43000000005648300 | D35: cont:air france global campaign::france | E35: N/A | F35: Air France Global Campaign | G35: France | H35: uncategorized | J35: Unassigned | K35: Unavailable | L35: 7.5 | M35: 49 | N35: 11 | O35: 0.22448979 | P35: 4780 | Q35: 1.0251046 | R35: 4.844477 | S35: 2.0408163 | T35: =N35/Y35 -> 11 | U35: 1296.25 | V35: =N35 -> 11 | W35: =U35-V35 -> 1285.25 | X35: =IF(V35=0,0,(U35-V35)/V35) -> 116.84091 | Y35: 1 | Z35: =IF(Y35=0,"NA",U35/Y35) -> 1296.25 | AA35: =(Q35/100*S35/100) -> 0.00020920502
A36: K435 | B36: Google - US | C36: 43000000017532124 | D36: airfrance.com | E36: Broad | F36: Air France Branded | G36: Air France Website | H36: uncategorized | J36: Unassigned | K36: Live | L36: 10 | M36: 1260 | N36: 365.79999 | O36: 0.29031745 | P36: 6231 | Q36: 20.221473 | R36: 1.0051709 | S36: 2.5396825 | T36: =N36/Y36 -> 11.43125 | U36: 42538.25 | V36: =N36 -> 365.79999 | W36: =U36-V36 -> 42172.45 | X36: =IF(V36=0,0,(U36-V36)/V36) -> 115.28828 | Y36: 32 | Z36: =IF(Y36=0,"NA",U36/Y36) -> 1329.3203 | AA36: =(Q36/100*S36/100) -> 0.0051356123
A37: K2615 | B37: Yahoo - US | C37: 43000000027382609 | D37: airfrance.us | E37: Advanced | F37: Air France Branded | G37: Air France Website | H37: uncategorized | J37: Unassigned | K37: Live | L37: 7.5 | M37: 242 | N37: 87.574999 | O37: 0.36188016 | P37: 1371 | Q37: 17.651349 | R37: 1.0201313 | S37: 5.785124 | T37: =N37/Y37 -> 6.2553571 | U37: 10140.5 | V37: =N37 -> 87.574999 | W37: =U37-V37 -> 10052.925 | X37: =IF(V37=0,0,(U37-V37)/V37) -> 114.79218 | Y37: 14 | Z37: =IF(Y37=0,"NA",U37/Y37) -> 724.32143 | AA37: =(Q37/100*S37/100) -> 0.010211524
A38: K435 | B38: Google - US | C38: 43000000013136095 | D38: book airfrance | E38: Broad | F38: Air France Branded | G38: Air France Brand | H38: uncategorized | I38: Position 1 -2 Target | J38: Unassigned | K38: Live | L38: 10 | M38: 4 | N38: 6 | O38: 1.5 | P38: 43 | Q38: 9.3023256 | R38: 1.0930233 | S38: 25 | T38: =N38/Y38 -> 6 | U38: 671.5 | V38: =N38 -> 6 | W38: =U38-V38 -> 665.5 | X38: =IF(V38=0,0,(U38-V38)/V38) -> 110.91667 | Y38: 1 | Z38: =IF(Y38=0,"NA",U38/Y38) -> 671.5 | AA38: =(Q38/100*S38/100) -> 0.023255814
A39: K1175 | B39: Google - Global | C39: 43000000005663350 | D39: nice flight | E39: Broad | F39: Air France Global Campaign | G39: Nice | H39: nice | I39: Position 1- 3 | J39: Unassigned | K39: Unavailable | L39: 1.25 | M39: 28 | N39: 36.425 | O39: 1.3008928 | P39: 2356 | Q39: 1.188455 | R39: 1.5467317 | S39: 10.714286 | T39: =N39/Y39 -> 12.141667 | U39: 3944 | V39: =N39 -> 36.425 | W39: =U39-V39 -> 3907.575 | X39: =IF(V39=0,0,(U39-V39)/V39) -> 107.27728 | Y39: 3 | Z39: =IF(Y39=0,"NA",U39/Y39) -> 1314.6667 | AA39: =(Q39/100*S39/100) -> 0.0012733447
A40: K435 | B40: Google - US | C40: 43000000017532142 | D40: airfrance.us | E40: Broad | F40: Air France Branded | G40: Air France Website | H40: uncategorized | J40: Unassigned | K40: Live | L40: 10 | M40: 25 | N40: 6.95 | O40: 0.278 | P40: 132 | Q40: 18.939394 | R40: 1 | S40: 4 | T40: =N40/Y40 -> 6.95 | U40: 751.4 | V40: =N40 -> 6.95 | W40: =U40-V40 -> 744.45 | X40: =IF(V40=0,0,(U40-V40)/V40) -> 107.11511 | Y40: 1 | Z40: =IF(Y40=0,"NA",U40/Y40) -> 751.4 | AA40: =(Q40/100*S40/100) -> 0.0075757576
...

Sheet data_cleaned
A1: Publisher Name | B1: Keyword | C1: Match Type | D1: Campaign | E1: Keyword Group | F1: Bid Strategy | G1: Search Engine Bid | H1: Clicks | I1: Click Charges | J1: Avg. Cost per Click | K1: Impressions | L1: Engine Click Thru % | M1: Avg. Pos. | N1: Trans. Conv. % | O1: Total Cost/ Trans. | P1: Total Revenue | Q1: Total Cost | R1: Net Revenue (Profit) | S1: Return on Ad Dollar Spent | T1: Total Volume of Bookings | U1: Avg. Revenue per Booking | V1: Probability of Booking | W1: Margin % | X1: Cost per Booking | Y1: Budgeted Cost | Z1: Budgeted Revenue | AA1: Cost Variance | AB1: Revenue Variance
A2: Yahoo - US | B2: fly to florence | C2: Advanced | D2: Western Europe Destinations | E2: Florence | G2: 6.25 | H2: 1 | I2: 2.3125 | J2: 2.3125 | K2: 11 | L2: 0.090909091 | M2: 1.2727273 | N2: 9 | O2: =I2/T2 -> 0.25694444 | P2: 8777.95 | Q2: =I2 -> 2.3125 | R2: =P2-Q2 -> 8775.6375 | S2: =IF(Q2=0,0,(P2-Q2)/Q2) -> 3794.8703 | T2: 9 | U2: =IF(T2=0,"NA",P2/T2) -> 975.32778 | V2: =(L2*N2) -> 0.81818182 | W2: =IF(P2=0,0,R2/P2) -> 0.99973656 | X2: =IF(T2=0,0,Q2/T2) -> 0.25694444 | Y2: =Q2*0.9 -> 2.08125 | Z2: =R2*1.05 -> 9214.4194 | AA2: =Q2-Y2 -> 0.23125 | AB2: =R2-Z2 -> -438.78188
A3: Yahoo - US | B3: low international airfare | C3: Advanced | D3: Geo Targeted DC | E3: Low International DC | G3: 6.25 | H3: 1 | I3: 0.625 | J3: 0.625 | K3: 6 | L3: 0.16666667 | M3: 1 | N3: 1 | O3: =I3/T3 -> 0.625 | P3: 1574.2 | Q3: =I3 -> 0.625 | R3: =P3-Q3 -> 1573.575 | S3: =IF(Q3=0,0,(P3-Q3)/Q3) -> 2517.72 | T3: 1 | U3: =IF(T3=0,"NA",P3/T3) -> 1574.2 | V3: =(L3*N3) -> 0.16666667 | W3: =IF(P3=0,0,R3/P3) -> 0.99960297 | X3: =IF(T3=0,0,Q3/T3) -> 0.625 | Y3: =Q3*0.9 -> 0.5625 | Z3: =R3*1.05 -> 1652.2538 | AA3: =Q3-Y3 -> 0.0625 | AB3: =R3-Z3 -> -78.67875
A4: MSN - Global | B4: air discount france ticket | C4: Broad | D4: Air France Brand & French Destinations | E4: France | F4: Position 2-5 Bid Strategy | G4: 0 | H4: 1 | I4: 0.3875 | J4: 0.3875 | K4: 9 | L4: 0.11111111 | M4: 1.1111111 | N4: 1 | O4: =I4/T4 -> 0.3875 | P4: 390.15 | Q4: =I4 -> 0.3875 | R4: =P4-Q4 -> 389.7625 | S4: =IF(Q4=0,0,(P4-Q4)/Q4) -> 1005.8387 | T4: 1 | U4: =IF(T4=0,"NA",P4/T4) -> 390.15 | V4: =(L4*N4) -> 0.11111111 | W4: =IF(P4=0,0,R4/P4) -> 0.99900679 | X4: =IF(T4=0,0,Q4/T4) -> 0.3875 | Y4: =Q4*0.9 -> 0.34875 | Z4: =R4*1.05 -> 409.25063 | AA4: =Q4-Y4 -> 0.03875 | AB4: =R4-Z4 -> -19.488125
A5: Google - Global | B5: [airfrance] | C5: Exact | D5: Air France Global Campaign | E5: Air France | F5: Position 1- 3 | G5: 7.5 | H5: 59 | I5: 2.3124998 | J5: 0.039194912 | K5: 401 | L5: 0.14713217 | M5: 2 | N5: 0.033898305 | O5: =I5/T5 -> 1.1562499 | P5: 1665.15 | Q5: =I5 -> 2.3124998 | R5: =P5-Q5 -> 1662.8375 | S5: =IF(Q5=0,0,(P5-Q5)/Q5) -> 719.06492 | T5: 2 | U5: =IF(T5=0,"NA",P5/T5) -> 832.575 | V5: =(L5*N5) -> 0.0049875312 | W5: =IF(P5=0,0,R5/P5) -> 0.99861124 | X5: =IF(T5=0,0,Q5/T5) -> 1.1562499 | Y5: =Q5*0.9 -> 2.0812499 | Z5: =R5*1.05 -> 1745.9794 | AA5: =Q5-Y5 -> 0.23124998 | AB5: =R5-Z5 -> -83.141875
A6: Overture - Global | B6: air france online booking | C6: Standard | D6: Unassigned | E6: Unassigned | F6: Position 1-2 Target | G6: 0.25 | H6: 8 | I6: 2.2 | J6: 0.275 | K6: 318 | L6: 0.025157233 | M6: 2.9757862 | N6: 0.125 | O6: =I6/T6 -> 2.2 | P6: 935 | Q6: =I6 -> 2.2 | R6: =P6-Q6 -> 932.8 | S6: =IF(Q6=0,0,(P6-Q6)/Q6) -> 424 | T6: 1 | U6: =IF(T6=0,"NA",P6/T6) -> 935 | V6: =(L6*N6) -> 0.0031446541 | W6: =IF(P6=0,0,R6/P6) -> 0.99764706 | X6: =IF(T6=0,0,Q6/T6) -> 2.2 | Y6: =Q6*0.9 -> 1.98 | Z6: =R6*1.05 -> 979.44 | AA6: =Q6-Y6 -> 0.22 | AB6: =R6-Z6 -> -46.64
A7: Overture - Global | B7: airfrance,com | C7: Standard | D7: Unassigned | E7: Unassigned | F7: Position 1-2 Target | G7: 0.125 | H7: 42 | I7: 5.25 | J7: 0.125 | K7: 722 | L7: 0.058171745 | M7: 1.1290859 | N7: 0.047619048 | O7: =I7/T7 -> 2.625 | P7: 1817.3 | Q7: =I7 -> 5.25 | R7: =P7-Q7 -> 1812.05 | S7: =IF(Q7=0,0,(P7-Q7)/Q7) -> 345.15238 | T7: 2 | U7: =IF(T7=0,"NA",P7/T7) -> 908.65 | V7: =(L7*N7) -> 0.0027700831 | W7: =IF(P7=0,0,R7/P7) -> 0.9971111 | X7: =IF(T7=0,0,Q7/T7) -> 2.625 | Y7: =Q7*0.9 -> 4.725 | Z7: =R7*1.05 -> 1902.6525 | AA7: =Q7-Y7 -> 0.525 | AB7: =R7-Z7 -> -90.6025
A8: Google - US | B8: paris cheap airline | C8: Broad | D8: Geo Targeted San Francisco | E8: San Francisco to Paris Sale | F8: Position 5-10 Bid Strategy | G8: 6.25 | H8: 3 | I8: 5.2125 | J8: 1.7375 | K8: 13 | L8: 0.23076923 | M8: 1 | N8: 0.33333333 | O8: =I8/T8 -> 5.2125 | P8: 1685.55 | Q8: =I8 -> 5.2125 | R8: =P8-Q8 -> 1680.3375 | S8: =IF(Q8=0,0,(P8-Q8)/Q8) -> 322.36691 | T8: 1 | U8: =IF(T8=0,"NA",P8/T8) -> 1685.55 | V8: =(L8*N8) -> 0.076923077 | W8: =IF(P8=0,0,R8/P8) -> 0.99690754 | X8: =IF(T8=0,0,Q8/T8) -> 5.2125 | Y8: =Q8*0.9 -> 4.69125 | Z8: =R8*1.05 -> 1764.3544 | AA8: =Q8-Y8 -> 0.52125 | AB8: =R8-Z8 -> -84.016875
A9: Overture - US | B9: airfrance.us | C9: Standard | D9: Unassigned | E9: Unassigned | F9: Position 1-4 Bid Strategy | G9: 0.325 | H9: 47 | I9: 11.8 | J9: 0.25106383 | K9: 547 | L9: 0.085923218 | M9: 1.1819013 | N9: 0.042553191 | O9: =I9/T9 -> 5.8999999 | P9: 3796.1 | Q9: =I9 -> 11.8 | R9: =P9-Q9 -> 3784.3 | S9: =IF(Q9=0,0,(P9-Q9)/Q9) -> 320.7034 | T9: 2 | U9: =IF(T9=0,"NA",P9/T9) -> 1898.05 | V9: =(L9*N9) -> 0.0036563071 | W9: =IF(P9=0,0,R9/P9) -> 0.99689155 | X9: =IF(T9=0,0,Q9/T9) -> 5.8999999 | Y9: =Q9*0.9 -> 10.62 | Z9: =R9*1.05 -> 3973.515 | AA9: =Q9-Y9 -> 1.18 | AB9: =R9-Z9 -> -189.215
A10: Overture - Global | B10: air travel to paris | C10: Standard | D10: Unassigned | E10: Unassigned | F10: Position 1-2 Target | G10: 7.5 | H10: 13 | I10: 5.2125 | J10: 0.40096154 | K10: 448 | L10: 0.029017857 | M10: 1.8564732 | N10: 0.076923077 | O10: =I10/T10 -> 5.2125 | P10: 1513 | Q10: =I10 -> 5.2125 | R10: =P10-Q10 -> 1507.7875 | S10: =IF(Q10=0,0,(P10-Q10)/Q10) -> 289.26379 | T10: 1 | U10: =IF(T10=0,"NA",P10/T10) -> 1513 | V10: =(L10*N10) -> 0.0022321429 | W10: =IF(P10=0,0,R10/P10) -> 0.99655486 | X10: =IF(T10=0,0,Q10/T10) -> 5.2125 | Y10: =Q10*0.9 -> 4.69125 | Z10: =R10*1.05 -> 1583.1769 | AA10: =Q10-Y10 -> 0.52125 | AB10: =R10-Z10 -> -75.389375
A11: Google - Global | B11: air france site | C11: Broad | D11: Air France Brand & French Destinations | E11: Air France Website | G11: 5 | H11: 19 | I11: 8.2374999 | J11: 0.43355262 | K11: 129 | L11: 0.14728682 | M11: 1.0302326 | N11: 0.052631579 | O11: =I11/T11 -> 8.2374999 | P11: 2348.55 | Q11: =I11 -> 8.2374999 | R11: =P11-Q11 -> 2340.3125 | S11: =IF(Q11=0,0,(P11-Q11)/Q11) -> 284.10471 | T11: 1 | U11: =IF(T11=0,"NA",P11/T11) -> 2348.55 | V11: =(L11*N11) -> 0.007751938 | W11: =IF(P11=0,0,R11/P11) -> 0.99649252 | X11: =IF(T11=0,0,Q11/T11) -> 8.2374999 | Y11: =Q11*0.9 -> 7.4137499 | Z11: =R11*1.05 -> 2457.3281 | AA11: =Q11-Y11 -> 0.82374999 | AB11: =R11-Z11 -> -117.01563
A12: Overture - Global | B12: cheap fare to paris | C12: Advanced | D12: Unassigned | E12: Unassigned | F12: Position 1-2 Target | G12: 0.6875 | H12: 29 | I12: 26.6125 | J12: 0.91767241 | K12: 559 | L12: 0.051878354 | M12: 2.3334526 | N12: 0.068965517 | O12: =I12/T12 -> 13.30625 | P12: 7418.8 | Q12: =I12 -> 26.6125 | R12: =P12-Q12 -> 7392.1875 | S12: =IF(Q12=0,0,(P12-Q12)/Q12) -> 277.77125 | T12: 2 | U12: =IF(T12=0,"NA",P12/T12) -> 3709.4 | V12: =(L12*N12) -> 0.0035778175 | W12: =IF(P12=0,0,R12/P12) -> 0.99641283 | X12: =IF(T12=0,0,Q12/T12) -> 13.30625 | Y12: =Q12*0.9 -> 23.95125 | Z12: =R12*1.05 -> 7761.7969 | AA12: =Q12-Y12 -> 2.66125 | AB12: =R12-Z12 -> -369.60938
A13: Overture - US | B13: air france.com | C13: Standard | D13: Unassigned | E13: Unassigned | F13: Position 1-4 Bid Strategy | G13: 0.3125 | H13: 273 | I13: 46.349998 | J13: 0.16978021 | K13: 3171 | L13: 0.086092715 | M13: 1.0063072 | N13: 0.036630037 | O13: =I13/T13 -> 4.6349998 | P13: 11271.85 | Q13: =I13 -> 46.349998 | R13: =P13-Q13 -> 11225.5 | S13: =IF(Q13=0,0,(P13-Q13)/Q13) -> 242.18987 | T13: 10 | U13: =IF(T13=0,"NA",P13/T13) -> 1127.185 | V13: =(L13*N13) -> 0.0031535793 | W13: =IF(P13=0,0,R13/P13) -> 0.99588799 | X13: =IF(T13=0,0,Q13/T13) -> 4.6349998 | Y13: =Q13*0.9 -> 41.714998 | Z13: =R13*1.05 -> 11786.775 | AA13: =Q13-Y13 -> 4.6349998 | AB13: =R13-Z13 -> -561.275
A14: Google - US | B14: air france us | C14: Broad | D14: Air France Branded | E14: Air France Website | G14: 10 | H14: 231 | I14: 99.549999 | J14: 0.43095237 | K14: 1277 | L14: 0.18089272 | M14: 1.0226077 | N14: 0.086580087 | O14: =I14/T14 -> 4.9774999 | P14: 23076.65 | Q14: =I14 -> 99.549999 | R14: =P14-Q14 -> 22977.1 | S14: =IF(Q14=0,0,(P14-Q14)/Q14) -> 230.80965 | T14: 20 | U14: =IF(T14=0,"NA",P14/T14) -> 1153.8325 | V14: =(L14*N14) -> 0.015661707 | W14: =IF(P14=0,0,R14/P14) -> 0.99568612 | X14: =IF(T14=0,0,Q14/T14) -> 4.9774999 | Y14: =Q14*0.9 -> 89.594999 | Z14: =R14*1.05 -> 24125.955 | AA14: =Q14-Y14 -> 9.9549999 | AB14: =R14-Z14 -> -1148.855
A15: Google - US | B15: airfrance | C15: Broad | D15: Air France Branded | E15: Air France Website | G15: 10 | H15: 907 | I15: 235.11249 | J15: 0.25921995 | K15: 4352 | L15: 0.20840993 | M15: 1.0105836 | N15: 0.028665932 | O15: =I15/T15 -> 9.0427883 | P15: 48551.15 | Q15: =I15 -> 235.11249 | R15: =P15-Q15 -> 48316.038 | S15: =IF(Q15=0,0,(P15-Q15)/Q15) -> 205.50179 | T15: 26 | U15: =IF(T15=0,"NA",P15/T15) -> 1867.3519 | V15: =(L15*N15) -> 0.0059742647 | W15: =IF(P15=0,0,R15/P15) -> 0.99515743 | X15: =IF(T15=0,0,Q15/T15) -> 9.0427883 | Y15: =Q15*0.9 -> 211.60125 | Z15: =R15*1.05 -> 50731.839 | AA15: =Q15-Y15 -> 23.511249 | AB15: =R15-Z15 -> -2415.8019
A16: Overture - US | B16: cdg flight | C16: Standard | D16: Unassigned | E16: Unassigned | F16: Position 2-5 Bid Strategy | G16: 0.125 | H16: 18 | I16: 4.75 | J16: 0.26388889 | K16: 169 | L16: 0.10650888 | M16: 1.6621302 | N16: 0.055555556 | O16: =I16/T16 -> 4.75 | P16: 896.75 | Q16: =I16 -> 4.75 | R16: =P16-Q16 -> 892 | S16: =IF(Q16=0,0,(P16-Q16)/Q16) -> 187.78947 | T16: 1 | U16: =IF(T16=0,"NA",P16/T16) -> 896.75 | V16: =(L16*N16) -> 0.0059171598 | W16: =IF(P16=0,0,R16/P16) -> 0.99470309 | X16: =IF(T16=0,0,Q16/T16) -> 4.75 | Y16: =Q16*0.9 -> 4.275 | Z16: =R16*1.05 -> 936.6 | AA16: =Q16-Y16 -> 0.475 | AB16: =R16-Z16 -> -44.6
A17: Google - US | B17: airfrance us | C17: Broad | D17: Air France Branded | E17: Air France Website | G17: 10 | H17: 207 | I17: 30.787498 | J17: 0.14873187 | K17: 730 | L17: 0.28356164 | M17: 1 | N17: 0.024154589 | O17: =I17/T17 -> 6.1574996 | P17: 5733.25 | Q17: =I17 -> 30.787498 | R17: =P17-Q17 -> 5702.4625 | S17: =IF(Q17=0,0,(P17-Q17)/Q17) -> 185.22007 | T17: 5 | U17: =IF(T17=0,"NA",P17/T17) -> 1146.65 | V17: =(L17*N17) -> 0.0068493151 | W17: =IF(P17=0,0,R17/P17) -> 0.99463001 | X17: =IF(T17=0,0,Q17/T17) -> 6.1574996 | Y17: =Q17*0.9 -> 27.708748 | Z17: =R17*1.05 -> 5987.5856 | AA17: =Q17-Y17 -> 3.0787498 | AB17: =R17-Z17 -> -285.12313
A18: Google - US | B18: france airline ticket | C18: Broad | D18: Geo Targeted New York | E18: New York to France Sale | F18: Position 5-10 Bid Strategy | G18: 6.25 | H18: 2 | I18: 2.6875 | J18: 1.34375 | K18: 24 | L18: 0.083333333 | M18: 1.5416667 | N18: 0.5 | O18: =I18/T18 -> 2.6875 | P18: 494.7 | Q18: =I18 -> 2.6875 | R18: =P18-Q18 -> 492.0125 | S18: =IF(Q18=0,0,(P18-Q18)/Q18) -> 183.07442 | T18: 1 | U18: =IF(T18=0,"NA",P18/T18) -> 494.7 | V18: =(L18*N18) -> 0.041666667 | W18: =IF(P18=0,0,R18/P18) -> 0.99456741 | X18: =IF(T18=0,0,Q18/T18) -> 2.6875 | Y18: =Q18*0.9 -> 2.41875 | Z18: =R18*1.05 -> 516.61312 | AA18: =Q18-Y18 -> 0.26875 | AB18: =R18-Z18 -> -24.600625
A19: Google - US | B19: airfrance website | C19: Broad | D19: Air France Branded | E19: Air France Website | F19: Position 2-5 Bid Strategy | G19: 0.7125 | H19: 10 | I19: 9.9375 | J19: 0.99375 | K19: 80 | L19: 0.125 | M19: 1.0625 | N19: 0.1 | O19: =I19/T19 -> 9.9375 | P19: 1815.6 | Q19: =I19 -> 9.9375 | R19: =P19-Q19 -> 1805.6625 | S19: =IF(Q19=0,0,(P19-Q19)/Q19) -> 181.70189 | T19: 1 | U19: =IF(T19=0,"NA",P19/T19) -> 1815.6 | V19: =(L19*N19) -> 0.0125 | W19: =IF(P19=0,0,R19/P19) -> 0.9945266 | X19: =IF(T19=0,0,Q19/T19) -> 9.9375 | Y19: =Q19*0.9 -> 8.94375 | Z19: =R19*1.05 -> 1895.9456 | AA19: =Q19-Y19 -> 0.99375 | AB19: =R19-Z19 -> -90.283125
A20: Overture - Global | B20: airplane france ticket | C20: Advanced | D20: Unassigned | E20: Unassigned | F20: Position 1-2 Target | G20: 0.4375 | H20: 16 | I20: 8.3125 | J20: 0.51953125 | K20: 6073 | L20: 0.0026346122 | M20: 2.4634283 | N20: 0.0625 | O20: =I20/T20 -> 8.3125 | P20: 1473.9 | Q20: =I20 -> 8.3125 | R20: =P20-Q20 -> 1465.5875 | S20: =IF(Q20=0,0,(P20-Q20)/Q20) -> 176.31128 | T20: 1 | U20: =IF(T20=0,"NA",P20/T20) -> 1473.9 | V20: =(L20*N20) -> 0.00016466326 | W20: =IF(P20=0,0,R20/P20) -> 0.9943602 | X20: =IF(T20=0,0,Q20/T20) -> 8.3125 | Y20: =Q20*0.9 -> 7.48125 | Z20: =R20*1.05 -> 1538.8669 | AA20: =Q20-Y20 -> 0.83125 | AB20: =R20-Z20 -> -73.279375
A21: Google - US | B21: france airfare sale | C21: Broad | D21: Geo Targeted Miami | E21: Miami to France Sale | F21: Position 5-10 Bid Strategy | G21: 6.25 | H21: 1 | I21: 2.7625 | J21: 2.7625 | K21: 2 | L21: 0.5 | M21: 1 | N21: 1 | O21: =I21/T21 -> 2.7625 | P21: 470.05 | Q21: =I21 -> 2.7625 | R21: =P21-Q21 -> 467.2875 | S21: =IF(Q21=0,0,(P21-Q21)/Q21) -> 169.15385 | T21: 1 | U21: =IF(T21=0,"NA",P21/T21) -> 470.05 | V21: =(L21*N21) -> 0.5 | W21: =IF(P21=0,0,R21/P21) -> 0.99412297 | X21: =IF(T21=0,0,Q21/T21) -> 2.7625 | Y21: =Q21*0.9 -> 2.48625 | Z21: =R21*1.05 -> 490.65188 | AA21: =Q21-Y21 -> 0.27625 | AB21: =R21-Z21 -> -23.364375
A22: Overture - Global | B22: air france schedule | C22: Advanced | D22: Unassigned | E22: Unassigned | F22: Position 1-2 Target | G22: 0.325 | H22: 30 | I22: 10.7125 | J22: 0.35708333 | K22: 2192 | L22: 0.013686131 | M22: 1.5193431 | N22: 0.033333333 | O22: =I22/T22 -> 10.7125 | P22: 1785 | Q22: =I22 -> 10.7125 | R22: =P22-Q22 -> 1774.2875 | S22: =IF(Q22=0,0,(P22-Q22)/Q22) -> 165.62778 | T22: 1 | U22: =IF(T22=0,"NA",P22/T22) -> 1785 | V22: =(L22*N22) -> 0.00045620438 | W22: =IF(P22=0,0,R22/P22) -> 0.9939986 | X22: =IF(T22=0,0,Q22/T22) -> 10.7125 | Y22: =Q22*0.9 -> 9.6412498 | Z22: =R22*1.05 -> 1863.0019 | AA22: =Q22-Y22 -> 1.07125 | AB22: =R22-Z22 -> -88.714375
A23: Overture - Global | B23: airfare to tahiti | C23: Standard | D23: Unassigned | E23: Unassigned | G23: 10 | H23: 6 | I23: 12.275 | J23: 2.0458333 | K23: 102 | L23: 0.058823529 | M23: 4.1637255 | N23: 0.16666667 | O23: =I23/T23 -> 12.275 | P23: 1989 | Q23: =I23 -> 12.275 | R23: =P23-Q23 -> 1976.725 | S23: =IF(Q23=0,0,(P23-Q23)/Q23) -> 161.03666 | T23: 1 | U23: =IF(T23=0,"NA",P23/T23) -> 1989 | V23: =(L23*N23) -> 0.0098039216 | W23: =IF(P23=0,0,R23/P23) -> 0.99382856 | X23: =IF(T23=0,0,Q23/T23) -> 12.275 | Y23: =Q23*0.9 -> 11.0475 | Z23: =R23*1.05 -> 2075.5613 | AA23: =Q23-Y23 -> 1.2275 | AB23: =R23-Z23 -> -98.83625
A24: Google - US | B24: france flights | C24: Broad | D24: Geo Targeted DC | E24: DC to France Sale | F24: Position 5-10 Bid Strategy | G24: 6.25 | H24: 6 | I24: 18.35 | J24: 3.0583333 | K24: 137 | L24: 0.04379562 | M24: 1.2026277 | N24: 0.5 | O24: =I24/T24 -> 6.1166666 | P24: 2810.1 | Q24: =I24 -> 18.35 | R24: =P24-Q24 -> 2791.75 | S24: =IF(Q24=0,0,(P24-Q24)/Q24) -> 152.13896 | T24: 3 | U24: =IF(T24=0,"NA",P24/T24) -> 936.7 | V24: =(L24*N24) -> 0.02189781 | W24: =IF(P24=0,0,R24/P24) -> 0.99346998 | X24: =IF(T24=0,0,Q24/T24) -> 6.1166666 | Y24: =Q24*0.9 -> 16.515 | Z24: =R24*1.05 -> 2931.3375 | AA24: =Q24-Y24 -> 1.835 | AB24: =R24-Z24 -> -139.5875
A25: Google - US | B25: international airfares | C25: Broad | D25: Geo Targeted Detroit | E25: International Detroit | F25: Position 5-10 Bid Strategy | G25: 6.25 | H25: 2 | I25: 6.6 | J25: 3.3 | K25: 79 | L25: 0.025316456 | M25: 3.0050633 | N25: 0.5 | O25: =I25/T25 -> 6.6 | P25: 923.95 | Q25: =I25 -> 6.6 | R25: =P25-Q25 -> 917.35 | S25: =IF(Q25=0,0,(P25-Q25)/Q25) -> 138.99242 | T25: 1 | U25: =IF(T25=0,"NA",P25/T25) -> 923.95 | V25: =(L25*N25) -> 0.012658228 | W25: =IF(P25=0,0,R25/P25) -> 0.99285676 | X25: =IF(T25=0,0,Q25/T25) -> 6.6 | Y25: =Q25*0.9 -> 5.94 | Z25: =R25*1.05 -> 963.2175 | AA25: =Q25-Y25 -> 0.66 | AB25: =R25-Z25 -> -45.8675
A26: Google - US | B26: france air ticket | C26: Broad | D26: Geo Targeted New York | E26: New York to France Sale | F26: Position 5-10 Bid Strategy | G26: 6.25 | H26: 12 | I26: 19.4 | J26: 1.6166667 | K26: 116 | L26: 0.10344828 | M26: 1.0940517 | N26: 0.33333333 | O26: =I26/T26 -> 4.85 | P26: 2706.4 | Q26: =I26 -> 19.4 | R26: =P26-Q26 -> 2687 | S26: =IF(Q26=0,0,(P26-Q26)/Q26) -> 138.50515 | T26: 4 | U26: =IF(T26=0,"NA",P26/T26) -> 676.6 | V26: =(L26*N26) -> 0.034482759 | W26: =IF(P26=0,0,R26/P26) -> 0.99283181 | X26: =IF(T26=0,0,Q26/T26) -> 4.85 | Y26: =Q26*0.9 -> 17.46 | Z26: =R26*1.05 -> 2821.35 | AA26: =Q26-Y26 -> 1.94 | AB26: =R26-Z26 -> -134.35
A27: Overture - US | B27: airfrance.com/us | C27: Standard | D27: Unassigned | E27: Unassigned | G27: 7.5 | H27: 17 | I27: 5.5874999 | J27: 0.32867646 | K27: 98 | L27: 0.17346939 | M27: 0.95918367 | N27: 0.058823529 | O27: =I27/T27 -> 5.5874999 | P27: 778.6 | Q27: =I27 -> 5.5874999 | R27: =P27-Q27 -> 773.0125 | S27: =IF(Q27=0,0,(P27-Q27)/Q27) -> 138.34676 | T27: 1 | U27: =IF(T27=0,"NA",P27/T27) -> 778.6 | V27: =(L27*N27) -> 0.010204082 | W27: =IF(P27=0,0,R27/P27) -> 0.99282366 | X27: =IF(T27=0,0,Q27/T27) -> 5.5874999 | Y27: =Q27*0.9 -> 5.0287499 | Z27: =R27*1.05 -> 811.66313 | AA27: =Q27-Y27 -> 0.55874999 | AB27: =R27-Z27 -> -38.650625
A28: Google - US | B28: paris cheap ticket | C28: Broad | D28: Geo Targeted Boston | E28: Boston to Paris Sale | F28: Position 5-10 Bid Strategy | G28: 6.25 | H28: 3 | I28: 5.1375 | J28: 1.7125 | K28: 18 | L28: 0.16666667 | M28: 1.8333333 | N28: 0.33333333 | O28: =I28/T28 -> 5.1375 | P28: 676.6 | Q28: =I28 -> 5.1375 | R28: =P28-Q28 -> 671.4625 | S28: =IF(Q28=0,0,(P28-Q28)/Q28) -> 130.6983 | T28: 1 | U28: =IF(T28=0,"NA",P28/T28) -> 676.6 | V28: =(L28*N28) -> 0.055555556 | W28: =IF(P28=0,0,R28/P28) -> 0.99240689 | X28: =IF(T28=0,0,Q28/T28) -> 5.1375 | Y28: =Q28*0.9 -> 4.62375 | Z28: =R28*1.05 -> 705.03562 | AA28: =Q28-Y28 -> 0.51375 | AB28: =R28-Z28 -> -33.573125
A29: Google - US | B29: paris cheap flights | C29: Broad | D29: Geo Targeted Houston | E29: Houston to Paris Sale | F29: Position 5-10 Bid Strategy | G29: 6.25 | H29: 21 | I29: 43.3875 | J29: 2.0660714 | K29: 174 | L29: 0.12068966 | M29: 1.3214368 | N29: 0.14285714 | O29: =I29/T29 -> 14.4625 | P29: 5638.05 | Q29: =I29 -> 43.3875 | R29: =P29-Q29 -> 5594.6625 | S29: =IF(Q29=0,0,(P29-Q29)/Q29) -> 128.94641 | T29: 3 | U29: =IF(T29=0,"NA",P29/T29) -> 1879.35 | V29: =(L29*N29) -> 0.017241379 | W29: =IF(P29=0,0,R29/P29) -> 0.99230452 | X29: =IF(T29=0,0,Q29/T29) -> 14.4625 | Y29: =Q29*0.9 -> 39.04875 | Z29: =R29*1.05 -> 5874.3956 | AA29: =Q29-Y29 -> 4.33875 | AB29: =R29-Z29 -> -279.73313
A30: Overture - US | B30: tunis | C30: Standard | D30: Unassigned | E30: Unassigned | F30: Position 1-4 Bid Strategy | G30: 11.25 | H30: 36 | I30: 25.375 | J30: 0.7048611 | K30: 832 | L30: 0.043269231 | M30: 1.4074519 | N30: 0.083333333 | O30: =I30/T30 -> 8.4583332 | P30: 3254.65 | Q30: =I30 -> 25.375 | R30: =P30-Q30 -> 3229.275 | S30: =IF(Q30=0,0,(P30-Q30)/Q30) -> 127.26207 | T30: 3 | U30: =IF(T30=0,"NA",P30/T30) -> 1084.8833 | V30: =(L30*N30) -> 0.0036057692 | W30: =IF(P30=0,0,R30/P30) -> 0.99220346 | X30: =IF(T30=0,0,Q30/T30) -> 8.4583332 | Y30: =Q30*0.9 -> 22.8375 | Z30: =R30*1.05 -> 3390.7388 | AA30: =Q30-Y30 -> 2.5375 | AB30: =R30-Z30 -> -161.46375
A31: Yahoo - US | B31: france travel agency | C31: Standard | D31: Paris & France Terms | E31: France | G31: 6.25 | H31: 5 | I31: 15.4375 | J31: 3.0875 | K31: 167 | L31: 0.02994012 | M31: 1.2392814 | N31: 0.4 | O31: =I31/T31 -> 7.71875 | P31: 1978.8 | Q31: =I31 -> 15.4375 | R31: =P31-Q31 -> 1963.3625 | S31: =IF(Q31=0,0,(P31-Q31)/Q31) -> 127.18138 | T31: 2 | U31: =IF(T31=0,"NA",P31/T31) -> 989.4 | V31: =(L31*N31) -> 0.011976048 | W31: =IF(P31=0,0,R31/P31) -> 0.99219855 | X31: =IF(T31=0,0,Q31/T31) -> 7.71875 | Y31: =Q31*0.9 -> 13.89375 | Z31: =R31*1.05 -> 2061.5306 | AA31: =Q31-Y31 -> 1.54375 | AB31: =R31-Z31 -> -98.168125
A32: Google - Global | B32: air france airlines | C32: Broad | D32: Air France Global Campaign | E32: Air France | F32: Position 1- 3 | G32: 1.25 | H32: 228 | I32: 55.312498 | J32: 0.24259868 | K32: 3747 | L32: 0.060848679 | M32: 1.4166533 | N32: 0.01754386 | O32: =I32/T32 -> 13.828124 | P32: 6873.1 | Q32: =I32 -> 55.312498 | R32: =P32-Q32 -> 6817.7875 | S32: =IF(Q32=0,0,(P32-Q32)/Q32) -> 123.25944 | T32: 4 | U32: =IF(T32=0,"NA",P32/T32) -> 1718.275 | V32: =(L32*N32) -> 0.0010675207 | W32: =IF(P32=0,0,R32/P32) -> 0.99195232 | X32: =IF(T32=0,0,Q32/T32) -> 13.828124 | Y32: =Q32*0.9 -> 49.781248 | Z32: =R32*1.05 -> 7158.6769 | AA32: =Q32-Y32 -> 5.5312498 | AB32: =R32-Z32 -> -340.88938
A33: Google - Global | B33: lyon airfare | C33: Broad | D33: Air France Global Campaign | E33: Lyon | F33: Position 1- 3 | G33: 1.25 | H33: 12 | I33: 15.025 | J33: 1.2520833 | K33: 1030 | L33: 0.011650485 | M33: 1.3096117 | N33: 0.16666667 | O33: =I33/T33 -> 7.5124999 | P33: 1836 | Q33: =I33 -> 15.025 | R33: =P33-Q33 -> 1820.975 | S33: =IF(Q33=0,0,(P33-Q33)/Q33) -> 121.19634 | T33: 2 | U33: =IF(T33=0,"NA",P33/T33) -> 918 | V33: =(L33*N33) -> 0.0019417476 | W33: =IF(P33=0,0,R33/P33) -> 0.99181645 | X33: =IF(T33=0,0,Q33/T33) -> 7.5124999 | Y33: =Q33*0.9 -> 13.5225 | Z33: =R33*1.05 -> 1912.0238 | AA33: =Q33-Y33 -> 1.5025 | AB33: =R33-Z33 -> -91.04875
A34: Overture - Global | B34: air france web site | C34: Standard | D34: Unassigned | E34: Unassigned | F34: Position 1-2 Target | G34: 0.2875 | H34: 17 | I34: 5.3875 | J34: 0.31691176 | K34: 752 | L34: 0.022606383 | M34: 2.2155585 | N34: 0.058823529 | O34: =I34/T34 -> 5.3875 | P34: 637.5 | Q34: =I34 -> 5.3875 | R34: =P34-Q34 -> 632.1125 | S34: =IF(Q34=0,0,(P34-Q34)/Q34) -> 117.32947 | T34: 1 | U34: =IF(T34=0,"NA",P34/T34) -> 637.5 | V34: =(L34*N34) -> 0.0013297872 | W34: =IF(P34=0,0,R34/P34) -> 0.99154902 | X34: =IF(T34=0,0,Q34/T34) -> 5.3875 | Y34: =Q34*0.9 -> 4.84875 | Z34: =R34*1.05 -> 663.71813 | AA34: =Q34-Y34 -> 0.53875 | AB34: =R34-Z34 -> -31.605625
A35: Google - Global | B35: cont:air france global campaign::france | C35: N/A | D35: Air France Global Campaign | E35: France | G35: 7.5 | H35: 49 | I35: 11 | J35: 0.22448979 | K35: 4780 | L35: 0.010251046 | M35: 4.844477 | N35: 0.020408163 | O35: =I35/T35 -> 11 | P35: 1296.25 | Q35: =I35 -> 11 | R35: =P35-Q35 -> 1285.25 | S35: =IF(Q35=0,0,(P35-Q35)/Q35) -> 116.84091 | T35: 1 | U35: =IF(T35=0,"NA",P35/T35) -> 1296.25 | V35: =(L35*N35) -> 0.00020920502 | W35: =IF(P35=0,0,R35/P35) -> 0.99151398 | X35: =IF(T35=0,0,Q35/T35) -> 11 | Y35: =Q35*0.9 -> 9.8999996 | Z35: =R35*1.05 -> 1349.5125 | AA35: =Q35-Y35 -> 1.1 | AB35: =R35-Z35 -> -64.2625
A36: Google - US | B36: airfrance.com | C36: Broad | D36: Air France Branded | E36: Air France Website | G36: 10 | H36: 1260 | I36: 365.79999 | J36: 0.29031745 | K36: 6231 | L36: 0.20221473 | M36: 1.0051709 | N36: 0.025396825 | O36: =I36/T36 -> 11.43125 | P36: 42538.25 | Q36: =I36 -> 365.79999 | R36: =P36-Q36 -> 42172.45 | S36: =IF(Q36=0,0,(P36-Q36)/Q36) -> 115.28828 | T36: 32 | U36: =IF(T36=0,"NA",P36/T36) -> 1329.3203 | V36: =(L36*N36) -> 0.0051356123 | W36: =IF(P36=0,0,R36/P36) -> 0.99140068 | X36: =IF(T36=0,0,Q36/T36) -> 11.43125 | Y36: =Q36*0.9 -> 329.21999 | Z36: =R36*1.05 -> 44281.073 | AA36: =Q36-Y36 -> 36.579999 | AB36: =R36-Z36 -> -2108.6225
A37: Yahoo - US | B37: airfrance.us | C37: Advanced | D37: Air France Branded | E37: Air France Website | G37: 7.5 | H37: 242 | I37: 87.574999 | J37: 0.36188016 | K37: 1371 | L37: 0.17651349 | M37: 1.0201313 | N37: 0.05785124 | O37: =I37/T37 -> 6.2553571 | P37: 10140.5 | Q37: =I37 -> 87.574999 | R37: =P37-Q37 -> 10052.925 | S37: =IF(Q37=0,0,(P37-Q37)/Q37) -> 114.79218 | T37: 14 | U37: =IF(T37=0,"NA",P37/T37) -> 724.32143 | V37: =(L37*N37) -> 0.010211524 | W37: =IF(P37=0,0,R37/P37) -> 0.99136384 | X37: =IF(T37=0,0,Q37/T37) -> 6.2553571 | Y37: =Q37*0.9 -> 78.817499 | Z37: =R37*1.05 -> 10555.571 | AA37: =Q37-Y37 -> 8.7574999 | AB37: =R37-Z37 -> -502.64625
A38: Google - US | B38: book airfrance | C38: Broad | D38: Air France Branded | E38: Air France Brand | F38: Position 1 -2 Target | G38: 10 | H38: 4 | I38: 6 | J38: 1.5 | K38: 43 | L38: 0.093023256 | M38: 1.0930233 | N38: 0.25 | O38: =I38/T38 -> 6 | P38: 671.5 | Q38: =I38 -> 6 | R38: =P38-Q38 -> 665.5 | S38: =IF(Q38=0,0,(P38-Q38)/Q38) -> 110.91667 | T38: 1 | U38: =IF(T38=0,"NA",P38/T38) -> 671.5 | V38: =(L38*N38) -> 0.023255814 | W38: =IF(P38=0,0,R38/P38) -> 0.99106478 | X38: =IF(T38=0,0,Q38/T38) -> 6 | Y38: =Q38*0.9 -> 5.4 | Z38: =R38*1.05 -> 698.775 | AA38: =Q38-Y38 -> 0.6 | AB38: =R38-Z38 -> -33.275
A39: Google - Global | B39: nice flight | C39: Broad | D39: Air France Global Campaign | E39: Nice | F39: Position 1- 3 | G39: 1.25 | H39: 28 | I39: 36.425 | J39: 1.3008928 | K39: 2356 | L39: 0.01188455 | M39: 1.5467317 | N39: 0.10714286 | O39: =I39/T39 -> 12.141667 | P39: 3944 | Q39: =I39 -> 36.425 | R39: =P39-Q39 -> 3907.575 | S39: =IF(Q39=0,0,(P39-Q39)/Q39) -> 107.27728 | T39: 3 | U39: =IF(T39=0,"NA",P39/T39) -> 1314.6667 | V39: =(L39*N39) -> 0.0012733447 | W39: =IF(P39=0,0,R39/P39) -> 0.99076445 | X39: =IF(T39=0,0,Q39/T39) -> 12.141667 | Y39: =Q39*0.9 -> 32.7825 | Z39: =R39*1.05 -> 4102.9538 | AA39: =Q39-Y39 -> 3.6425 | AB39: =R39-Z39 -> -195.37875
A40: Google - US | B40: airfrance.us | C40: Broad | D40: Air France Branded | E40: Air France Website | G40: 10 | H40: 25 | I40: 6.95 | J40: 0.278 | K40: 132 | L40: 0.18939394 | M40: 1 | N40: 0.04 | O40: =I40/T40 -> 6.95 | P40: 751.4 | Q40: =I40 -> 6.95 | R40: =P40-Q40 -> 744.45 | S40: =IF(Q40=0,0,(P40-Q40)/Q40) -> 107.11511 | T40: 1 | U40: =IF(T40=0,"NA",P40/T40) -> 751.4 | V40: =(L40*N40) -> 0.0075757576 | W40: =IF(P40=0,0,R40/P40) -> 0.9907506 | X40: =IF(T40=0,0,Q40/T40) -> 6.95 | Y40: =Q40*0.9 -> 6.255 | Z40: =R40*1.05 -> 781.6725 | AA40: =Q40-Y40 -> 0.695 | AB40: =R40-Z40 -> -37.2225
...

Sheet P&L Pivot Table
A3: Row Labels | B3: Sum of Net Revenue (Profit) | C3: Sum of Total Cost | D3: Sum of Total Volume of Bookings | E3: Sum of Budgeted Revenue | F3: Sum of Budgeted Cost | G3: Sum of Revenue Variance | H3: Sum of Cost Variance | I3: Average of Margin % | J3: Average of Engine Click Thru % | K3: Average of Cost per Booking | L3: Average of RevenuePerBooking
A4: Google - Global | B4: 808603.09 | C4: 120946.71 | D4: 797 | E4: 849033.24 | F4: 108852.04 | G4: -40430.154 | H4: 12094.671 | I4: 0.10474101 | J4: 0.089944849 | K4: 70.896472 | L4: 1166.3109
A5: Google - US | B5: 1391841.2 | C5: 353640.6 | D5: 1550 | E5: 1461433.3 | F5: 318276.54 | G5: -69592.06 | H5: 35364.06 | I5: 0.016028189 | J5: 0.15089745 | K5: 25.116883 | L5: 1126.1173
A6: MSN - Global | B6: 133363.89 | C6: 12160.362 | D6: 129 | E6: 140032.08 | F6: 10944.326 | G6: -6668.1944 | H6: 1216.0362 | I6: 0.089814572 | J6: 0.073356049 | K6: 11.165817 | L6: 1128.095
A7: MSN - US | B7: 165451.31 | C7: 16098.487 | D7: 140 | E7: 173723.88 | F7: 14488.639 | G7: -8272.5656 | H7: 1609.8487 | I7: 0.086432537 | J7: 0.08263521 | K7: 5.1577145 | L7: 1296.7843
A8: Overture - Global | B8: 365788.84 | C8: 64295.862 | D8: 372 | E8: 384078.28 | F8: 57866.276 | G8: -18289.442 | H8: 6429.5862 | I8: 0.057960813 | J8: 0.035478634 | K8: 16.468699 | L8: 1156.1417
A9: Overture - US | B9: 205457.18 | C9: 141976.07 | D9: 289 | E9: 215730.03 | F9: 127778.47 | G9: -10272.859 | H9: 14197.607 | I9: 0.015226643 | J9: 0.026728464 | K9: 43.660687 | L9: 1202.1912
A10: Yahoo - US | B10: 836091.13 | C10: 46197.825 | D10: 662 | E10: 877895.68 | F10: 41578.042 | G10: -41804.556 | H10: 4619.7825 | I10: 0.044443465 | J10: 0.16059019 | K10: 7.9565704 | L10: 1332.7628
A11: Grand Total | B11: 3906596.6 | C11: 755315.92 | D11: 3939 | E11: 4101926.5 | F11: 679784.33 | G11: -195329.83 | H11: 75531.592 | I11: 0.035933119 | J11: 0.11141451 | K11: 27.607445 | L11: 1183.5269

Sheet Top 10 Campaigns by Revenue
A3: Row Labels | B3: Average of Net Revenue (Profit)
A4: Air France Branded | B4: 30230.042
A5: Google - US | B5: 35086.965
A6: Yahoo - US | B6: 24342.863
A7: Air France Brand & French Destinations | B7: 2307.9847
A8: Google - Global | B8: 3627.753
A9: MSN - Global | B9: 1347.11
A10: MSN - US | B10: 1761.5201
A11: Air France Global Campaign | B11: 1439.4415
A12: Google - Global | B12: 1439.4415
A13: General Terms | B13: 1371.475
A14: Yahoo - US | B14: 1371.475
A15: Unassigned | B15: 470.54861
... A72: Google - US | B72: -114.58805

Sheet ROAS by Campaign
A3: Row Labels | B3: Average of Return on Ad Dollar Spent
A4: Air France Brand & French Destinations | B4: 5.4135137
A5: Air France Branded | B5: 30.494118
A6: Air France Global Campaign | B6: 4.8639168
A7: Business Class | B7: -0.99720645
A8: French Destinations | B8: -0.58365977
A9: General Terms | B9: 2.2613875
A10: Geo Targeted Atlanta | B10: -0.75380605
A11: Geo Targeted Boston | B11: 0.1083371
A12: Geo Targeted Chicago | B12: 0.45151159
A13: Geo Targeted Cincinnati | B13: -1
A14: Geo Targeted DC | B14: 17.724148
A15: Geo Targeted Detroit | B15: 0.33326118
... A27: Western Europe Destinations | B27: 9.0219604

Sheet Combo Chart
A3: Row Labels | B3: Average of Cost per Booking | C3: Average of Revenue per Booking
A4: Google - Global | B4: 70.896472 | C4: 1166.3109
A5: Google - US | B5: 25.116883 | C5: 1126.1173
A6: MSN - Global | B6: 11.165817 | C6: 1128.095
A7: MSN - US | B7: 5.1577145 | C7: 1296.7843
A8: Overture - Global | B8: 16.468699 | C8: 1156.1417
A9: Overture - US | B9: 43.660687 | C9: 1202.1912
A10: Yahoo - US | B10: 7.9565704 | C10: 1332.7628
A11: Grand Total | B11: 27.607445 | C11: 1183.5269

Sheet Pivot Table
A3: Row Labels | B3: Sum of Impressions | C3: Sum of Clicks | D3: Sum of Total Cost | E3: Sum of Net Revenue (Profit) | F3: Sum of Total Volume of Bookings | G3: Average of Cost per Click | H3: Sum of Trans. Conv. % | I3: Sum of Total Revenue
A4: Air France Brand & French Destinations | B4: 573159 | C4: 57674 | D4: 87014.537 | E4: 701627.36 | F4: 699 | G4: 1.5087307 | H4: 2.4989034 | I4: 788641.9
A5: Air France Branded | B5: 1263310 | C5: 143174 | D5: 143077.82 | E5: 2206793.1 | F5: 1932 | G5: 0.99932826 | H5: 1.3293698 | I5: 2349870.9
A6: Air France Global Campaign | B6: 1540074 | C6: 37221 | D6: 62059.45 | E6: 405922.5 | F6: 367 | G6: 1.6673235 | H6: 1.0403178 | I6: 467981.95
A7: Business Class | B7: 41878 | C7: 655 | D7: 3269.05 | E7: -3124.55 | F7: 1 | G7: 4.990916 | H7: 0.0034602076 | I7: 144.5
A8: French Destinations | B8: 59351 | C8: 3701 | D8: 8431.7375 | E8: -2208.0375 | F8: 14 | G8: 2.2782322 | H8: 0.17274532 | I8: 6223.7
A9: General Terms | B9: 144298 | C9: 518 | D9: 606.475 | E9: 1371.475 | F9: 1 | G9: 1.1708011 | H9: 0.0019305019 | I9: 1977.95
A10: Geo Targeted Atlanta | B10: 4428 | C10: 129 | D10: 265.25 | E10: -95.25 | F10: 1 | G10: 2.0562015 | H10: 0.16666667 | I10: 170
A11: Geo Targeted Boston | B11: 16137 | C11: 538 | D11: 1396.175 | E11: 1482.775 | F11: 4 | G11: 2.5951208 | H11: 0.40304487 | I11: 2878.95
A12: Geo Targeted Chicago | B12: 12690 | C12: 682 | D12: 1581.675 | E12: 5562.575 | F12: 5 | G12: 2.3191715 | H12: 0.25769709 | I12: 7144.25
A13: Geo Targeted Cincinnati | B13: 676 | C13: 16 | D13: 33.75 | E13: -33.75 | F13: 0 | G13: 2.109375 | H13: 0 | I13: 0
A14: Geo Targeted DC | B14: 19875 | C14: 512 | D14: 1271.3625 | E14: 3920.4375 | F14: 9 | G14: 2.4831299 | H14: 2.1969697 | I14: 5191.8
A15: Geo Targeted Detroit | B15: 9648 | C15: 295 | D15: 719.025 | E15: 204.925 | F15: 1 | G15: 2.4373729 | H15: 0.5 | I15: 923.95
... A28: Grand Total | B28: 41868674 | C28: 512849 | D28: 755315.92 | E28: 3906596.6 | F28: 3939 | G28: 1.4727842 | H28: 25.673404 | I28: 4661912.6

Sheet Scenario Analysis
A1: Campaign | B1: Impressions | C1: Cost per Click | D1: Trans. Conv. % | E1: Revenue per Booking | F1: Current CTR | G1: Current Profit | H1: Profit Target | I1: Required CTR | M1: Clicks | N1: Total Cost | O1: Bookings | P1: Total Revenue
A2: ='Pivot Table'!A4 -> Air France Brand & French Destinations | B2: =GETPIVOTDATA("Sum of Impressions",'Pivot Table'!$A$3,"Campaign",$A2) -> 573159 | C2: =$N2/$M2 -> 1.5087307 | D2: =GETPIVOTDATA("Sum of Trans. Conv. %",'Pivot Table'!$A$3,"Campaign",$A2) -> 2.4989034 | E2: =IF($O2=0, 0, $P2/$O2) -> 1128.2431 | F2: =$M2/$B2 -> 0.10062478 | G2: =GETPIVOTDATA("Sum of Net Revenue (Profit)",'Pivot Table'!$A$3,"Campaign",$A2) -> 701627.36 | H2: =IF($G2>0, G2*1.2, 0) -> 841952.84 | I2: =$H2 / ( $B2 * ( ($D2/100) * $E2 - $C2 ) ) -> 0.055048549 | M2: =GETPIVOTDATA("Sum of Clicks",'Pivot Table'!$A$3,"Campaign",$A2) -> 57674 | N2: =GETPIVOTDATA("Sum of Total Cost",'Pivot Table'!$A$3,"Campaign",$A2) -> 87014.537 | O2: =GETPIVOTDATA("Sum of Total Volume of Bookings",'Pivot Table'!$A$3,"Campaign",$A2) -> 699 | P2: =GETPIVOTDATA("Sum of Total Revenue",'Pivot Table'!$A$3,"Campaign",$A2) -> 788641.9
A3: ='Pivot Table'!A5 -> Air France Branded | B3: =GETPIVOTDATA("Sum of Impressions",'Pivot Table'!$A$3,"Campaign",$A3) -> 1263310 | C3: =$N3/$M3 -> 0.99932826 | D3: =GETPIVOTDATA("Sum of Trans. Conv. %",'Pivot Table'!$A$3,"Campaign",$A3) -> 1.3293698 | E3: =IF($O3=0, 0, $P3/$O3) -> 1216.2893 | F3: =$M3/$B3 -> 0.11333244 | G3: =GETPIVOTDATA("Sum of Net Revenue (Profit)",'Pivot Table'!$A$3,"Campaign",$A3) -> 2206793.1 | H3: =IF($G3>0, G3*1.2, 1000) -> 2648151.7 | I3: =$H3 / ( $B3 * ( ($D3/100) * $E3 - $C3 ) ) -> 0.13818383 | M3: =GETPIVOTDATA("Sum of Clicks",'Pivot Table'!$A$3,"Campaign",$A3) -> 143174 | N3: =GETPIVOTDATA("Sum of Total Cost",'Pivot Table'!$A$3,"Campaign",$A3) -> 143077.82 | O3: =GETPIVOTDATA("Sum of Total Volume of Bookings",'Pivot Table'!$A$3,"Campaign",$A3) -> 1932 | P3: =GETPIVOTDATA("Sum of Total Revenue",'Pivot Table'!$A$3,"Campaign",$A3) -> 2349870.9
A4: ='Pivot Table'!A6 -> Air France Global Campaign | B4: =GETPIVOTDATA("Sum of Impressions",'Pivot Table'!$A$3,"Campaign",$A4) -> 1540074 | C4: =$N4/$M4 -> 1.6673235 | D4: =GETPIVOTDATA("Sum of Trans. Conv. %",'Pivot Table'!$A$3,"Campaign",$A4) -> 1.0403178 | E4: =IF($O4=0, 0, $P4/$O4) -> 1275.1552 | F4: =$M4/$B4 -> 0.024168319 | G4: =GETPIVOTDATA("Sum of Net Revenue (Profit)",'Pivot Table'!$A$3,"Campaign",$A4) -> 405922.5 | H4: =IF($G4>0, G4*1.2, 1000) -> 487107 | I4: =$H4 / ( $B4 * ( ($D4/100) * $E4 - $C4 ) ) -> 0.027270106 | M4: =GETPIVOTDATA("Sum of Clicks",'Pivot Table'!$A$3,"Campaign",$A4) -> 37221 | N4: =GETPIVOTDATA("Sum of Total Cost",'Pivot Table'!$A$3,"Campaign",$A4) -> 62059.45 | O4: =GETPIVOTDATA("Sum of Total Volume of Bookings",'Pivot Table'!$A$3,"Campaign",$A4) -> 367 | P4: =GETPIVOTDATA("Sum of Total Revenue",'Pivot Table'!$A$3,"Campaign",$A4) -> 467981.95
A5: ='Pivot Table'!A7 -> Business Class | B5: =GETPIVOTDATA("Sum of Impressions",'Pivot Table'!$A$3,"Campaign",$A5) -> 41878 | C5: =$N5/$M5 -> 4.990916 | D5: =GETPIVOTDATA("Sum of Trans. Conv. %",'Pivot Table'!$A$3,"Campaign",$A5) -> 0.0034602076 | E5: =IF($O5=0, 0, $P5/$O5) -> 144.5 | F5: =$M5/$B5 -> 0.015640671 | G5: =GETPIVOTDATA("Sum of Net Revenue (Profit)",'Pivot Table'!$A$3,"Campaign",$A5) -> -3124.55 | H5: =IF($G5>0, G5*1.2, 1000) -> 1000 | I5: =$H5 / ( $B5 * ( ($D5/100) * $E5 - $C5 ) ) -> -0.0047892676 | M5: =GETPIVOTDATA("Sum of Clicks",'Pivot Table'!$A$3,"Campaign",$A5) -> 655 | N5: =GETPIVOTDATA("Sum of Total Cost",'Pivot Table'!$A$3,"Campaign",$A5) -> 3269.05 | O5: =GETPIVOTDATA("Sum of Total Volume of Bookings",'Pivot Table'!$A$3,"Campaign",$A5) -> 1 | P5: =GETPIVOTDATA("Sum of Total Revenue",'Pivot Table'!$A$3,"Campaign",$A5) -> 144.5
A6: ='Pivot Table'!A8 -> French Destinations | B6: =GETPIVOTDATA("Sum of Impressions",'Pivot Table'!$A$3,"Campaign",$A6) -> 59351 | C6: =$N6/$M6 -> 2.2782322 | D6: =GETPIVOTDATA("Sum of Trans. Conv. %",'Pivot Table'!$A$3,"Campaign",$A6) -> 0.17274532 | E6: =IF($O6=0, 0, $P6/$O6) -> 444.55 | F6: =$M6/$B6 -> 0.062357837 | G6: =GETPIVOTDATA("Sum of Net Revenue (Profit)",'Pivot Table'!$A$3,"Campaign",$A6) -> -2208.0375 | H6: =IF($G6>0, G6*1.2, 1000) -> 1000 | I6: =$H6 / ( $B6 * ( ($D6/100) * $E6 - $C6 ) ) -> -0.011156058 | M6: =GETPIVOTDATA("Sum of Clicks",'Pivot Table'!$A$3,"Campaign",$A6) -> 3701 | N6: =GETPIVOTDATA("Sum of Total Cost",'Pivot Table'!$A$3,"Campaign",$A6) -> 8431.7375 | O6: =GETPIVOTDATA("Sum of Total Volume of Bookings",'Pivot Table'!$A$3,"Campaign",$A6) -> 14 | P6: =GETPIVOTDATA("Sum of Total Revenue",'Pivot Table'!$A$3,"Campaign",$A6) -> 6223.7
A7: ='Pivot Table'!A9 -> General Terms | B7: =GETPIVOTDATA("Sum of Impressions",'Pivot Table'!$A$3,"Campaign",$A7) -> 144298 | C7: =$N7/$M7 -> 1.1708011 | D7: =GETPIVOTDATA("Sum of Trans. Conv. %",'Pivot Table'!$A$3,"Campaign",$A7) -> 0.0019305019 | E7: =IF($O7=0, 0, $P7/$O7) -> 1977.95 | F7: =$M7/$B7 -> 0.0035897933 | G7: =GETPIVOTDATA("Sum of Net Revenue (Profit)",'Pivot Table'!$A$3,"Campaign",$A7) -> 1371.475 | H7: =IF($G7>0, G7*1.2, 1000) -> 1645.77 | I7: =$H7 / ( $B7 * ( ($D7/100) * $E7 - $C7 ) ) -> -0.010069916 | M7: =GETPIVOTDATA("Sum of Clicks",'Pivot Table'!$A$3,"Campaign",$A7) -> 518 | N7: =GETPIVOTDATA("Sum of Total Cost",'Pivot Table'!$A$3,"Campaign",$A7) -> 606.475 | O7: =GETPIVOTDATA("Sum of Total Volume of Bookings",'Pivot Table'!$A$3,"Campaign",$A7) -> 1 | P7: =GETPIVOTDATA("Sum of Total Revenue",'Pivot Table'!$A$3,"Campaign",$A7) -> 1977.95
A8: ='Pivot Table'!A10 -> Geo Targeted Atlanta | B8: =GETPIVOTDATA("Sum of Impressions",'Pivot Table'!$A$3,"Campaign",$A8) -> 4428 | C8: =$N8/$M8 -> 2.0562015 | D8: =GETPIVOTDATA("Sum of Trans. Conv. %",'Pivot Table'!$A$3,"Campaign",$A8) -> 0.16666667 | E8: =IF($O8=0, 0, $P8/$O8) -> 170 | F8: =$M8/$B8 -> 0.029132791 | G8: =GETPIVOTDATA("Sum of Net Revenue (Profit)",'Pivot Table'!$A$3,"Campaign",$A8) -> -95.25 | H8: =IF($G8>0, G8*1.2, 1000) -> 1000 | I8: =$H8 / ( $B8 * ( ($D8/100) * $E8 - $C8 ) ) -> -0.12738431 | M8: =GETPIVOTDATA("Sum of Clicks",'Pivot Table'!$A$3,"Campaign",$A8) -> 129 | N8: =GETPIVOTDATA("Sum of Total Cost",'Pivot Table'!$A$3,"Campaign",$A8) -> 265.25 | O8: =GETPIVOTDATA("Sum of Total Volume of Bookings",'Pivot Table'!$A$3,"Campaign",$A8) -> 1 | P8: =GETPIVOTDATA("Sum of Total Revenue",'Pivot Table'!$A$3,"Campaign",$A8) -> 170
